package exception;

import static org.hamcrest.CoreMatchers.instanceOf;
import static org.junit.Assert.assertEquals;
import static org.junit.Assert.assertThat;
import static org.junit.Assert.fail;

import org.junit.Test;

import model.Calculator;

public class CalculatorTestEx {

	// Kiểm tra ngoại lệ ném ra có đúng hay không
	@Test(expected = ArithmeticException.class)
	public void testDivideForException() {
		Calculator calculator = new Calculator();
		calculator.divide(9, 0);
	}

	@Test
	public void testDivideWithTryCatch() {
		Calculator calculator = new Calculator();
		try {
			int result = calculator.divide(9, 0);
			fail("Not found exception");
		} catch (Exception e) {
			assertThat(e, instanceOf(ArithmeticException.class));
			assertEquals("Divide by zero", e.getMessage());
		}
	}

}
